<?xml version=”1.0”?>
<robot name=”mybot”>
	
	<!-- FOOTPRINT -->

	<link name="footprint"/>

	<joint name="base_joint" type="fixed">
	  <parent link="footprint"/>
	  <child link="chassis"/>
	</joint>	
	

	<!-- CHASSIS -->

	<link name='chassis'>
	  <collision> 
	    <origin xyz="0 0 0.1" rpy="0 0 0"/> 
	    <geometry> 
	      <box size="0.4 0.2 0.1"/> 
	    </geometry> 
	  </collision>
	  <visual> 
	    <origin xyz="0 0 0.1" rpy="0 0 0"/> 
	    <geometry> 
	      <box size="0.4 0.2 0.1"/> 
	    </geometry>
	  </visual>
	  <inertial> 
	    <origin xyz="0 0 0.1" rpy="0 0 0"/> 
	    <mass value="50"/> 
	    <inertia ixx="0.208" ixy="0" ixz="0" iyy="0.708" iyz="0" izz="0.708"/>
	  </inertial>
	</link>
	
	<gazebo reference="chassis">
	  <material>Gazebo/Orange</material>
	</gazebo>
	

	<!-- CASTER WHEEL -->
	
	<joint name="fixed" type="fixed">
	  <parent link="chassis"/>
	  <child link="caster_wheel"/>
	</joint>

	<link name="caster_wheel">
	  <collision>
		<origin xyz="-0.15 0 0.05" rpy="0 0 0"/>
		<geometry>
		  <sphere radius="0.05"/>
		</geometry>
	  </collision>
	  
	  <visual>
		<origin xyz="-0.15 0 0.05" rpy="0 0 0"/>
		<geometry>
		  <sphere radius="0.05"/>
		</geometry>
	  </visual>

	  <inertial>
		<origin xyz="-0.15 0 0.05" rpy="0 0 0"/>
		<mass value="5"/>
		<inertia ixx="0.005" ixy="0" ixz="0" iyy="0.005" iyz="0" izz="0.005" />
	  </inertial>
	</link>
	
	<gazebo reference="caster_wheel">
	  <mu1>0.0</mu1>
	  <mu2>0.0</mu2>
	  <material>Gazebo/Red</material>
	</gazebo>
	
	
	
	<!-- LEFT WHEEL -->
	
	<joint name="left_wheel_hinge" type="continuous">
	  <parent link="chassis"/>
	  <child link="left_wheel"/>
	<origin xyz="0 0.125 0.1" rpy="0 0 0" />
	  <axis xyz="0 1 0" rpy="0 0 0" />
	  <limit effort="100" velocity="100"/>
	  <joint_properties damping="0.0" friction="0.0"/>
	</joint>
	
	<link name="left_wheel">
	  <collision>
		<origin xyz="0 0 0" rpy="0 1.57 1.57" />
		<geometry>
		  <cylinder length="0.05" radius="0.1"/>
		</geometry>
	  </collision>

	  <visual>
		<origin xyz="0 0 0" rpy="0 1.57 1.57" />
		<geometry>
		  <cylinder length="0.05" radius="0.1"/>
		</geometry>
	  </visual>

	  <inertial>
		<origin xyz="0 0 0" rpy="0 1.57 1.57" />
		<mass value="5"/>
		<inertia ixx="0.0135" ixy="0" ixz="0" iyy="0.0135" iyz="0" izz="0.025" />
	  </inertial>
	</link>

	<gazebo reference="left_wheel">
	  <mu1 value="1.0"/>
	  <mu2 value="1.0"/>
	  <material>Gazebo/Black</material>
	</gazebo>
	
	

	<!-- RIGHT WHEEL -->
	
	<joint name="right_wheel_hinge" type="continuous">
	  <parent link="chassis"/>
	  <child link="right_wheel"/>
	<origin xyz="0 -0.125 0.1" rpy="0 0 0" />
	  <axis xyz="0 1 0" rpy="0 0 0" />
	  <limit effort="100" velocity="100"/>
	  <joint_properties damping="0.0" friction="0.0"/>
	</joint>
	
	<link name="right_wheel">
	  <collision>
		<origin xyz="0 0 0" rpy="0 1.57 1.57" />
		<geometry>
		  <cylinder length="0.05" radius="0.1"/>
		</geometry>
	  </collision>

	  <visual>
		<origin xyz="0 0 0" rpy="0 1.57 1.57" />
		<geometry>
		  <cylinder length="0.05" radius="0.1"/>
		</geometry>
	  </visual>

	  <inertial>
		<origin xyz="0 0 0" rpy="0 1.57 1.57" />
		<mass value="5"/>
		<inertia ixx="0.0135" ixy="0" ixz="0" iyy="0.0135" iyz="0" izz="0.025" />
	  </inertial>
	</link>

	<gazebo reference="right_wheel">
	  <mu1 value="1.0"/>
	  <mu2 value="1.0"/>
	  <material>Gazebo/Black</material>
	</gazebo>
	
	<gazebo>
	  <plugin name="differential_drive_controller" filename="libgazebo_ros_diff_drive.so">
		<alwaysOn>true</alwaysOn>
		<updateRate>100</updateRate>
		<leftJoint>left_wheel_hinge</leftJoint>
		<rightJoint>right_wheel_hinge</rightJoint>
		<wheelSeparation>0.25</wheelSeparation>
		<wheelDiameter>0.2</wheelDiameter>
		<torque>20</torque>
		<commandTopic>mybot/cmd_vel</commandTopic>
		<odometryTopic>mybot/odom</odometryTopic>
		<odometryFrame>odom</odometryFrame>
		<robotBaseFrame>footprint</robotBaseFrame>
	  </plugin>
	</gazebo>
	 
	 
	 
	 <!-- LASER -->
	<joint name="laser_joint" type="fixed">
		<origin xyz="0.15 0 0.2" rpy="0 0 0"/>
		<parent link="chassis"/>
		<child link="laser_link"/>
	</joint>

	<link name="laser_link">
		<collision>
			<origin xyz="0 0 0" rpy="0 0 0"/>
			<geometry>
				<box size="0.1 0.1 0.1"/>
			</geometry>
		</collision>

		<visual>
			<origin xyz="0 0 0" rpy="0 0 0"/>
			<geometry>
				<box size="0.1 0.1 0.1"/>
			</geometry>
		</visual>

		<inertial>
			<mass value="1e-5" />
			<origin xyz="0 0 0" rpy="0 0 0"/>
			<inertia ixx="1e-6" ixy="0" ixz="0" iyy="1e-6" iyz="0" izz="1e-6" />
		</inertial>
	</link>
	 
	 
	<gazebo reference="laser_link">
		<sensor type="ray" name="laser">
			<pose>0 0 0 0 0 0</pose>
			<visualize>true</visualize>
			<update_rate>40</update_rate>
			<ray>
				<scan>
					<horizontal>
						<samples>8</samples>
						<resolution>1</resolution>
						<min_angle>-3.14159</min_angle>
						<max_angle>3.14159</max_angle>
					</horizontal>
				</scan>
				<range>
					<min>0.10</min>
					<max>10.0</max>
					<resolution>0.01</resolution>
				</range>
			</ray>
			<plugin name="laser_controller" filename="libgazebo_ros_laser.so">
				<topicName>mybot/scan</topicName>
				<frameName>base_link</frameName>
			</plugin>
		</sensor>
	</gazebo>

</robot>













